I'm sorry, but an uncaught exception occurred.

While running game code:
<<<<<<< HEAD
  File "game/main_room.rpy", line 14, in script
    b "Back here again..."
Exception: Sayer 'b' is not defined.
=======
  File "game/script.rpy", line 22, in script call
    call lucia_room #start in lucia's room
  File "game/main_room.rpy", line 58, in script
    jump launch_deck
ScriptError: could not find label 'launch_deck'.
>>>>>>> refs/remotes/origin/main

-- Full Traceback ------------------------------------------------------------

Full traceback:
<<<<<<< HEAD
  File "game/main_room.rpy", line 14, in script
    b "Back here again..."
  File "D:\renpy-8.0.3-sdk\renpy\ast.py", line 881, in execute
    who = eval_who(self.who, self.who_fast)
  File "D:\renpy-8.0.3-sdk\renpy\ast.py", line 774, in eval_who
    raise Exception("Sayer '%s' is not defined." % who)
Exception: Sayer 'b' is not defined.
=======
  File "game/script.rpy", line 22, in script call
    call lucia_room #start in lucia's room
  File "game/main_room.rpy", line 58, in script
    jump launch_deck
  File "D:\renpy-8.0.3-sdk.7z\renpy-8.0.3-sdk\renpy\ast.py", line 1974, in execute
    rv = renpy.game.script.lookup(target)
  File "D:\renpy-8.0.3-sdk.7z\renpy-8.0.3-sdk\renpy\script.py", line 927, in lookup
    raise ScriptError("could not find label '%s'." % str(original))
ScriptError: could not find label 'launch_deck'.
>>>>>>> refs/remotes/origin/main

Windows-10-10.0.19045 AMD64
Ren'Py 8.0.3.22090809
GAME NAME HERE 1.0
<<<<<<< HEAD
Sat Apr  1 23:43:11 2023
=======
Sun Apr  2 00:14:54 2023
>>>>>>> refs/remotes/origin/main
